Workbook
Name DATA: Table_1[]
Name Category: 'Size Options'!$C$2:$C$4389
Name Size: 'Size Options'!$B$2:$B$4408
Name Categ: #REF!
Name Category_v: 'Size Options'!$A$2:$A$4408
Name Sizes: 'Size Options'!$A$2:$B$4408
Name Sub_Cat: #REF!
Name Colors: 'Color Mapping'!$A$1:$A$15

Sheet START HERE Instructions
A1: GETTING STARTED
A2: Bulk Upload is an advanced listing management tool that allows you to create and manage listings in bulk on Poshmark faster and more efficiently than ever before.
A3: If this is your first time, begin by using this spreadsheet to create a couple of Draft listings to begin, and review the listing details to ensure they’re appearing as desired.
A5: List More: Inventory sitting around that you haven’t gotten around to listing? With Bulk Upload, you can list more inventory utilizing spreadsheets to create multiple listings at once. | J5: s
A6: List Faster: You no longer have to copy and paste your listing details into our Single Listing Creation form. With Bulk Upload, you can quickly copy your listing details into our spreadsheet templates.
A7: If you’re creating multiple listings with similar listing details, replicate the listing details in multiple cells easily using Excel’s copy and drag features.
A8: Inventory Management: You can use the same file to action listings by simply adding new listings into your existing file. Listings that already exist in your closet will not be duplicated.
A9: This way, your file can act as a spreadsheet version of your closet, used to manage and track all your listings.
A11: GUIDELINES
A12: 1. When creating new listings or editing existing ones, all columns in red are required. Required fields indicate the baseline values needed to create or edit listings.
A13: Tip: Download My Inventory Report to quickly populate many of the listing details for existing listings in your closet.
A14: 2. Some fields will have dropdown menus to select from and some fields will be free form text. For the fields with free form text, please take note of character and symbol limitations noted on the legend below.
A15: 3. Each row of the spreadsheet equates to one size of the listing.
A16: 4. We determine whether you are intending to Create new listings or Edit existing ones based on the SKU value in column A.
A17: 4a. If the SKU does not exist in your closet, we will create a new listing with the given listing details.
A18: 4b. If the SKU input matches the SKU of an existing listing in your closet, we will edit that listing to match to new listing details provided in your most recent file upload.
... A75: Table 1.1
A76: SKU | B76: Title | C76: Quantity | D76: Size | E76: VariantGroupID | F76: VariantType | G76: VariantAttribute
A77: (Required) Unique SKU per size (you create this!) | B77: (Required) What are you selling? | C77: (Required) How many? Specific to the size listed | D77: (Required) Select from dropdown Item sizing? Each row is a unique size | E77: Required for multi-item listings Also known as Listing SKU, is consistent across Variant | F77: Required for multi-item listings Select from dropdown | G77: Use for multi-item listings Select from dropdown
A78: BLUEPANT00S | B78: High Waisted Relaxed Fit Jean | C78: 4 | D78: S | E78: BLUPNT001 | F78: Parent | G78: Size
A79: BLUEPANT00M | C79: 5 | D79: M | E79: BLUPNT001 | F79: Child
A80: BLUEPANT00L | C80: 7 | D80: L | E80: BLUPNT001 | F80: Child
A81: BLUEPANT00XL | C81: 8 | D81: XL | E81: BLUPNT001 | F81: Child

Sheet Legend
A2: LEGEND
A3: Attribute | B3: Possible values | C3: Description
A4: SKU Required 500 Character Limit Max 4 Character Limit Min | B4: TTL-0004-3333 BLUEPANT012 | C4: A stock-keeping unit (SKU) is a product identifier for a specific item. SKUs have to be unique to each item.
A5: ProductID 14 Character Limit Max | B5: 194610749753 00614141000012 | C5: UPCs and GTINs are found on the item tag and are created by original manufacturer. Either a UPC or a GTIN can be provided.
A6: Title Required 80 Character Limit Max | B6: Poshmark Fashion Gold Beaded Cocktail Dress (S) | C6: Share key details about what you're selling like Brand, Size, and Color.
A7: Description Required 1500 Character Limit Max | B7: This little number is so stunning in person. It will be a great piece to have once party season picks up again! There are some stains in the lining, it is hardly noticeable. Please refer to photos, price adjusted accordingly. | C7: Tell shoppers about your listing by describing the Brand, Size, Color, Condition, Material, and any other noteworthy details. To create a blank line, you must enter a newline directly into the cell. No special characters or html accepted. See possible values for example.
A8: Department Required | B8: Women Men | C8: Add the department that your item falls into.
A9: Category Required | B9: Women Accessories Men Shoes | C9: Add details about what your item is to help your buyers find your item quickly.
A10: Sub-Category | B10: Womens Accessories Hats Mens Shoes Boots | C10: Add further details about the type of sub-category that your item best fits in.
A11: Quantity Required | B11: 3 | C11: Share how many units of the item that you have available. The quantity is specific to the size listed and each row should equate to one size. If you have 3 of the exact same skirts in the same size, then this number would be 3.
A12: Size Required | B12: S M L | C12: Select sizes appropriate for your products' market, category, and sub-category from the size dropdown on the create listing page and enter the corresponding value in this spreadsheet. Custom sizes can be entered but should only be used sparingly.
A13: Condition Required | B13: NWT Like New Good Fair | C13: Condition signifies the state of the item at the time of listing creation. New With Tags (NWT): Brand new with original tags or packaging Like New: New without tags or like new Good: Gently used with minimal signs of wear, to note in description or photos Fair: Clearly used with visible wear, to note in description or photos
A14: Brand | B14: Poshmark Fashion | C14: Add details about who produced the item to help your buyers find your item quickly.
A15: Color (1-2) | B15: Blue Red | C15: Select up to two colors via the dropdown. One color per column.
A16: VariantGroupID 50 Character Limit Max VariantType VariantAttribute | B16: VariantGroupID: RedDressGR1 VariantType: Parent VariantAttribute: Size VariantGroupID: RedDressGR1 VariantType: Child | C16: For creating a listing with multiple size variations, there will be a parent-child relationship for the following fields: VariantGroupID VariantType VariantAttribute See specific directions above in the HOW TO UPLOAD VARIANTS section and examples in Table 1.1
A17: Style Tag (1-3) 25 Character Limit Max | B17: 90's A-Line Abstract Acrylic Animal Print Art Deco | C17: Make it easy for buyers to find your listings by selecting or creating up to 3 tags to describe your item (aesthetic, material, style, etc.). Buyers will be able to search and browse our catalog using style tags. Style tags are alphanumeric text strings that can include the following special characters: ' apostrophe - Dash (Hyphen-Minus) & Ampersand Space
A18: Original Price Required | B18: 100 | C18: The original price of the item when first purchased. Please round pricing to whole dollar amounts (no decimals), i.e. whole USD
A19: Listing Price Required | B19: 75 | C19: The price you want to list the item at. Please round pricing to whole amounts, i.e. whole USD
A20: Shipping Discount | B20: <blank> 4.99 FREE | C20: PoshPost allows for items to be shipped with a prepaid label via USPS. Buyers pay a flat fee for shipping. Sellers have the option to include discounted shipping. Standard shipping rate applies if this column is left blank.
A21: Availability Required | B21: For Sale Not for Sale Drops Draft | C21: Select the availabilty of the listing that you would like at the time of publish. If "For Sale", "Not for Sale", or "Drops" is selected, items will immediately appear in your closet if no errors occur during item setup. If "Drops" is selected, "Drop time" becomes a required attribute and indicated the time that the item should become available for purchase. If "Draft" is selected, items will be setup as "Draft" listings. Selecting Draft allows you to review your new listings before manually publishing them to your closet. You can find your draft folder on the create listing page. Please note that if you prefer to upload images from mobile or at a later time, you would choose "Draft" as the availability. Once saved and uploaded to drafts, you can upload individually from your device.
A22: Drop time Required when Drops selected for Availability | B22: 02/08/21 12 PM 02/08/21 12:30 PM | C22: If "Drops" is selected, enter the drop time for a "drops soon" listing to indicate the time that the item should become available for purchase. Drop time must be within 7 days from initial file upload. MM/DD/YY HH:MM AM/PM (available in 30min increments only)
A23: Other Info 500 Character Limit Max | C23: This is an opportunity to write yourself private notes about a specific item. This field is only visible to you on "edit listing" page. Cells support plain text only, no bulleted list or text formatting.
A24: Copy Listing? | B24: Y N | C24: Are you cloning or copying an existing listing? If copying, mark Y for yes or N for no.
A25: Update Existing SKU? | B25: Y | C25: Are you updating the SKU of an existing listing? Mark Y for yes.
A26: New SKU Required when Update Existing SKU is marked Y 500 Character Limit Max | B26: TTL-0004-3333 BLUEPANT012 | C26: Enter the new SKU you would like to update the existing listing to. As a reminder, a stock-keeping unit (SKU) is a product identifier for a specific item. SKUs have to be unique to each item. SKUs can contain only the following special characters: - Dash
A27: Primary Image Required when Availability is marked For Sale, Not for Sale, or Drops 400 Character Limit Max | B27: https://di2ponv0v5otw.cloudfront.net/posts/2019/09/03/5d6ea243b146cc18281e18f6/m_5d6ea2627a81732d756feffc.jpg | C27: The Primary image is the Covershot for the listing. DO have a clear view of the main product being sold DO accurately display the entire product. DO use a solid white or transparent background color. DON’T use props that cover the product. DON’T use a generic image, graphic, or illustration. DON’T use an image with a border or watermark. See image specific directions above in the HOW TO UPLOAD PHOTOS section.
A28: Alt Image 1-15 400 Character Limit Max | B28: https://di2ponv0v5otw.cloudfront.net/posts/2019/09/03/5d6ea243b146cc18281e18f6/m_5d6ea264248f7a5a12051247.jpg | C28: Option to add up to 15 alt images for each listing. Alt images should be supplemental to main images and should show different elements or details of the product. Alt image examples are the back, sides, and tags of the item. See image specific directions above in the HOW TO UPLOAD PHOTOS section.

Sheet Dept Cat Subcat Taxonomy
A1: Department | B1: Category | C1: Subcategory
A2: Women | B2: Dresses | C2: Asymmetrical
A3: Women | B3: Dresses | C3: Backless
A4: Women | B4: Dresses | C4: High Low
A5: Women | B5: Dresses | C5: Long Sleeve
A6: Women | B6: Dresses | C6: Maxi
A7: Women | B7: Dresses | C7: Midi
A8: Women | B8: Dresses | C8: Mini
A9: Women | B9: Dresses | C9: One Shoulder
A10: Women | B10: Dresses | C10: Prom
A11: Women | B11: Dresses | C11: Strapless
A12: Women | B12: Dresses | C12: Wedding
... A634: Electronics | B634: Portable Audio & Video | C634: Radios

Sheet Size Taxonomy
A1: Category | B1: Size
A2: Accessories | B2: OS
A3: Accessories | B3: OSEU
A4: Accessories | B4: OSAU
A5: Accessories | B5: OSUK
A6: Bags | B6: OS
A7: Bags | B7: OSEU
A8: Bags | B8: OSAU
A9: Bags | B9: OSUK
A10: Jewelry | B10: OS
A11: Jewelry | B11: OSEU
A12: Jewelry | B12: OSAU
... A21: Other | B21: OSUK
A22: Shoes | B22: 5
A23: Shoes | B23: 5.5
A24: Shoes | B24: 6
A25: Shoes | B25: 6.5
A26: Shoes | B26: 7
A27: Shoes | B27: 7.5
A28: Shoes | B28: 8
A29: Shoes | B29: 8.5
A30: Shoes | B30: 9
A31: Shoes | B31: 9.5
A32: Shoes | B32: 10
A33: Shoes | B33: 10.5
... A38: Shoes | B38: 13
A39: Shoes | B39: 34.5EU
A40: Shoes | B40: 35EU
A41: Shoes | B41: 35.5EU
A42: Shoes | B42: 36EU
A43: Shoes | B43: 36.5EU
A44: Shoes | B44: 37EU
A45: Shoes | B45: 37.5EU
A46: Shoes | B46: 38EU
A47: Shoes | B47: 38.5EU
A48: Shoes | B48: 39EU
A49: Shoes | B49: 39.5EU
A50: Shoes | B50: 40EU
... A91: Shoes | B91: 11UK
A92: Dresses | B92: 0
...

Sheet Examples
A1: SKU | B1: ProductID (GTIN) | C1: Title | D1: Description | E1: Department | F1: Category | G1: Sub-category | H1: Quantity | I1: Size | J1: Condition | K1: Brand | L1: Color1 | M1: Color2 | N1: VariantGroupID | O1: VariantType | P1: VariantAttribute | Q1: Style Tag1 | R1: Style Tag2 | S1: Style Tag3 | T1: Orig price | U1: Listing price | V1: Shipping Discount | W1: Price Floor Percent | X1: Minimum Price | Y1: Availability | Z1: Drop time | AA1: Other info | AB1: Copy Listing? | AC1: Update Existing SKU? | AD1: NEW SKU | AE1: Primary image | AF1: Alt image 1 | AG1: Alt image 2 | AH1: Alt image 3 | AI1: Alt image 4 | AJ1: Alt image 5 | AK1: Alt image 6 | AL1: Alt image 7 | AM1: Alt image 8 | AN1: Alt image 9 | AO1: Alt image 10 | AP1: Alt image 11 | AQ1: Alt image 12 | AR1: Alt image 13 | AS1: Alt image 14 | AT1: Alt image 15
A2: (Required) Unique SKU per size (you create this!) | B2: UPC / GTIN | C2: (Required) What are you selling? | D2: (Required) Plain text only No bulleted lists No text formatting Newline characters accepted | E2: (Required) Select from dropdown | F2: (Required) Select from dropdown | G2: Select from dropdown | H2: (Required) How many? Specific to the size listed | I2: (Required) Select from dropdown Item sizing? Each row is a unique size | J2: NWT Like New Good Fair | K2: Brand or designer | L2: Select from dropdown | M2: Select from dropdown | N2: Required for multi-item listings Also known as Listing SKU, is consistent across Variant | O2: Required for multi-item listings Select from dropdown | P2: Use for multi-item listings Select from dropdown | Q2: Describe the aesthetic, style, etc | R2: Describe the aesthetic, style, etc | S2: Describe the aesthetic, style, etc | T2: (Required) Original price of item | U2: (Required) Your item price | V2: Select from Dropdown Leave blank for No Shipping Discount. | W2: Turns on Smart Sell, a tool that automates sending, countering, and accepting offers based on your price floor percent. Enter a whole number representing the largest percent off the Listing Price (no % sign) that you are willing to accept. Fill in either this field or Minimum Price, not both. Leave blank to keep Smart Sell off. | X2: Turns on Smart Sell, a tool that automates sending, countering, and accepting offers based on your minimum price. Enter the minimum acceptable price as a number (no $ symbol). Fill in either this field or Price Floor Percent, not both. Leave blank to keep Smart Sell off. | Y2: (Required) For Sale, Not for Sale, Draft, or Drops | Z2: Date and Time for Drops Soon listing | AA2: Private notes about the item | AB2: Are you Copying an existing listing vs creating it for the first time? | AC2: Are you updating an existing sku? | AD2: (Required if updating) | AE2: (Required for all availability types except Drafts) URL to image from online cloud | AF2: URL to image | AG2: URL to image | AH2: URL to image | AI2: URL to image | AJ2: URL to image | AK2: URL to image | AL2: URL to image | AM2: URL to image | AN2: URL to image | AO2: URL to image | AP2: URL to image | AQ2: URL to image | AR2: URL to image | AS2: URL to image | AT2: URL to image
A3: REDDRESS001 | B3: 194610749754 | C3: SINGLE ITEM LISTING EXAMPLE | D3: This little number is so stunning in person. It will be a great piece to have once party season picks up again! There are some stains in the lining, it is hardly noticeable. Please refer to photos, price adjusted accordingly. MEASUREMENTS: Length (Shoulder to hem): 33", Bust: 19", Waist: 20" | E3: Women | F3: Dresses | G3: Long Sleeve | H3: 1 | I3: S | L3: Red | M3: Black | Q3: Bohemian | R3: Silk | T3: 168 | U3: 75 | W3: 30 | Y3: For Sale | AA3: Bin123 | AE3: https://di2ponv0v5otw.cloudfront.net/posts/2019/09/03/5d6ea243b146cc18281e18f6/m_5d6ea2627a81732d756feffc.jpg | AF3: https://di2ponv0v5otw.cloudfront.net/posts/2019/09/03/5d6ea243b146cc18281e18f6/m_5d6ea264248f7a5a12051247.jpg | AG3: https://di2ponv0v5otw.cloudfront.net/posts/2019/09/03/5d6ea243b146cc18281e18f6/m_5d6ea266afade89d82a4cd84.jpg
A4: BLUEPANT000 | B4: 194610749753 | C4: MULTI ITEM LISTING EXAMPLE | D4: You deserve to live in comfort so start from the bottom in these soft elastic waist wide-leg pants. Style with your favorite loose-fit graphic t-shirt. 48% Rayon 48% Polyester 4% Spandex. Please note that we are unable to negotiate the listing price at this time therefore the listing price is firm. We ask that you please do not send in any offers at the time. Thank you for your understanding! | E4: Women | F4: Pants & Jumpsuits | G4: Wide Leg | H4: 4 | I4: 0 | J4: NWT | L4: Blue | N4: BLUPNT001 | O4: Parent | P4: Size | Q4: Luxury | T4: 150 | U4: 50 | W4: 10 | Y4: For Sale | AA4: Bin124 | AE4: https://di2ponv0v5otw.cloudfront.net/posts/2019/09/03/5d6ea243b146cc18281e18f6/m_5d6ea2627a81732d756feffc.jpg | AF4: https://di2ponv0v5otw.cloudfront.net/posts/2019/09/03/5d6ea243b146cc18281e18f6/m_5d6ea264248f7a5a12051247.jpg | AG4: https://di2ponv0v5otw.cloudfront.net/posts/2019/09/03/5d6ea243b146cc18281e18f6/m_5d6ea266afade89d82a4cd84.jpg
A5: BLUEPANT002 | B5: 194610749746 | H5: 5 | I5: 2 | J5: NWT | N5: BLUPNT001 | O5: Child
A6: BLUEPANT004 | B6: 194610749739 | H6: 7 | I6: 4 | J6: NWT | N6: BLUPNT001 | O6: Child
A7: BLUEPANT006 | B7: 194610749760 | H7: 8 | I7: 6 | J7: NWT | N7: BLUPNT001 | O7: Child
A8: BLUEPANT008 | B8: 194610749722 | H8: 8 | I8: 8 | J8: NWT | N8: BLUPNT001 | O8: Child
A9: BLUEPANT010 | B9: 194610749777 | H9: 6 | I9: 10 | J9: NWT | N9: BLUPNT001 | O9: Child
A10: BLUEPANT012 | B10: 194610749814 | H10: 3 | I10: 12 | J10: NWT | N10: BLUPNT001 | O10: Child

Sheet Listing Details
A1: SKU | B1: ProductID (GTIN) | C1: Title | D1: Description | E1: Department | F1: Category | G1: Sub-category | H1: Quantity | I1: Size | J1: Condition | K1: Brand | L1: Color1 | M1: Color2 | N1: VariantGroupID | O1: VariantType | P1: VariantAttribute | Q1: Style Tag1 | R1: Style Tag2 | S1: Style Tag3 | T1: Orig price | U1: Listing price | V1: Shipping Discount | W1: Price Floor Percent | X1: Minimum Price | Y1: Availability | Z1: Drop time | AA1: Other info | AB1: Copy Listing? | AC1: Update Existing SKU? | AD1: NEW SKU | AE1: Primary image | AF1: Alt image 1 | AG1: Alt image 2 | AH1: Alt image 3 | AI1: Alt image 4 | AJ1: Alt image 5 | AK1: Alt image 6 | AL1: Alt image 7 | AM1: Alt image 8 | AN1: Alt image 9 | AO1: Alt image 10 | AP1: Alt image 11 | AQ1: Alt image 12 | AR1: Alt image 13 | AS1: Alt image 14 | AT1: Alt image 15
A2: (Required) Unique SKU per size (you create this!) | B2: UPC / GTIN | C2: (Required) What are you selling? | D2: (Required) Plain text only No bulleted lists No text formatting Newline characters accepted | E2: (Required) Select from dropdown | F2: (Required) Select from dropdown or copy from Taxonomy tab | G2: Select from dropdown or copy from Taxonomy tab | H2: (Required) How many? Specific to the size listed | I2: (Required) Select from dropdown or copy from Taxonomy tab. Item sizing? Each row is a unique size | J2: NWT Like New Good Fair | K2: Brand or designer | L2: Select from dropdown | M2: Select from dropdown | N2: Required for multi-item listings Also known as Listing SKU, is consistent across Variant | O2: Required for multi-item listings Select from dropdown | P2: Use for multi-item listings Select from dropdown | Q2: Describe the aesthetic, style, etc | R2: Describe the aesthetic, style, etc | S2: Describe the aesthetic, style, etc | T2: (Required) Original price of item | U2: (Required) Your item price | V2: Select from Dropdown Leave blank for No Shipping Discount. | W2: Turns on Smart Sell, a tool that automates sending, countering, and accepting offers based on your price floor percent. Enter a whole number representing the largest percent off the Listing Price (no % sign) that you are willing to accept. Fill in either this field or Minimum Price, not both. Leave blank to keep Smart Sell off. | X2: Turns on Smart Sell, a tool that automates sending, countering, and accepting offers based on your minimum price. Enter the minimum acceptable price as a number (no $ symbol). Fill in either this field or Price Floor Percent, not both. Leave blank to keep Smart Sell off. | Y2: (Required) For Sale, Not for Sale, Draft, or Drops | Z2: Date and Time for Drops Soon listing | AA2: Private notes about the item | AB2: Are you Copying an existing listing vs creating it for the first time? | AC2: Are you updating an existing sku? | AD2: (Required if updating) | AE2: (Required for all availability types except Drafts) URL to image from online cloud | AF2: URL to image | AG2: URL to image | AH2: URL to image | AI2: URL to image | AJ2: URL to image | AK2: URL to image | AL2: URL to image | AM2: URL to image | AN2: URL to image | AO2: URL to image | AP2: URL to image | AQ2: URL to image | AR2: URL to image | AS2: URL to image | AT2: URL to image
A3: FP001 | C3: NWT Free People Carpe Diem Shorts - Black - S | D3: NWT Free People Carpe Diem Shorts - Black - S Perfect for your next run or workout, these FP Movement shorts feature a high-rise, stretch-knit waistband and a relaxed fit. Crafted from durable, water-resistant fabric, they include built-in briefs for extra coverage and a convenient interior waistband pocket for small essentials. The effortless pull-on design ensures maximum comfort and support through every movement. Brand new with tags and the original retail price of $40.00 | E3: Women | F3: Shorts | H3: 2 | I3: S | J3: NWT | K3: Free People | L3: Black | N3: FP001 | Q3: Athletic | R3: Activewear | T3: 40 | U3: 30 | Y3: Not For Sale | AE3: https://images.urbndata.com/is/image/FreePeople/88138201_001_g/?$a15-pdp-detail-shot$&fit=constrain&fmt=webp&qlt=80&wid=1314
A4: FP003 | C4: NWT Free People Carpe Diem Short - Blueberry - S | D4: NWT Free People Carpe Diem Short - Blueberry - S The Carpe Diem shorts from FP Movement feature a relaxed, high-waisted fit designed for both performance and lounging. Crafted from durable, water-resistant fabric, these shorts include built-in briefs for added coverage and a comfortable stretch-knit waistband with a hidden interior pocket. Brand new with tags and the original retail price of $40.00 | E4: Women | F4: Shorts | H4: 1 | I4: S | J4: NWT | K4: Free People | L4: Blue | Q4: Athletic | R4: Activewear | T4: 40 | U4: 30 | Y4: Not For Sale | AE4: https://images.urbndata.com/is/image/FreePeople/88138201_048_b/?$a15-pdp-detail-shot$&fit=constrain&fmt=webp&qlt=80&wid=1314
A5: FP005 | C5: NWT Free People Carpe Diem Short - Pink/Rose | D5: NWT Free People Carpe Diem Short - Pink/Rose The Carpe Diem shorts from FP Movement feature a relaxed, high-waisted fit designed for both performance and lounging. Crafted from durable, water-resistant fabric, these shorts include built-in briefs for added coverage and a comfortable stretch-knit waistband with a hidden interior pocket. Brand new with tags and the original retail price of $40.00 | E5: Women | F5: Shorts | H5: 2 | I5: S | J5: NWT | K5: Free People | L5: Pink | N5: FPCPPINK1 | O5: Parent | P5: Size | Q5: Athletic | R5: Activewear | T5: 40 | U5: 30 | Y5: Not For Sale | AE5: https://images.urbndata.com/is/image/FreePeople/88138201_066_e/?$redesign-zoom-5x$
A6: FP006 | C6: NWT Free People Carpe Diem Short - Pink/Rose | D6: NWT Free People Carpe Diem Short - Pink/Rose The Carpe Diem shorts from FP Movement feature a relaxed, high-waisted fit designed for both performance and lounging. Crafted from durable, water-resistant fabric, these shorts include built-in briefs for added coverage and a comfortable stretch-knit waistband with a hidden interior pocket. Brand new with tags and the original retail price of $40.00 | E6: Women | F6: Shorts | H6: 3 | I6: M | J6: NWT | K6: Free People | L6: Pink | N6: FPCPPINK1 | O6: Child | Q6: Athletic | R6: Activewear | T6: 40 | U6: 30 | Y6: Not For Sale | AE6: https://images.urbndata.com/is/image/FreePeople/88138201_001_g/?$a15-pdp-detail-shot$&fit=constrain&fmt=webp&qlt=80&wid=1314
A7: FP007 | C7: NWT Free People Carpe Diem Short - Pink/Rose | D7: NWT Free People Carpe Diem Short - Pink/Rose The Carpe Diem shorts from FP Movement feature a relaxed, high-waisted fit designed for both performance and lounging. Crafted from durable, water-resistant fabric, these shorts include built-in briefs for added coverage and a comfortable stretch-knit waistband with a hidden interior pocket. Brand new with tags and the original retail price of $40.00 | E7: Women | F7: Shorts | H7: 1 | I7: XS | J7: NWT | K7: Free People | L7: Pink | N7: FPCPPINK1 | O7: Child | Q7: Athletic | R7: Activewear | T7: 40 | U7: 30 | Y7: Not For Sale | AE7: https://images.urbndata.com/is/image/FreePeople/88138201_001_g/?$a15-pdp-detail-shot$&fit=constrain&fmt=webp&qlt=80&wid=1314
A8: FP008 | C8: NWT Free People Carpe Diem Short - Red - M | D8: NWT Free People Carpe Diem Short - Red The Carpe Diem shorts from FP Movement feature a relaxed, high-waisted fit designed for both performance and lounging. Crafted from durable, water-resistant fabric, these shorts include built-in briefs for added coverage and a comfortable stretch-knit waistband with a hidden interior pocket. Brand new with tags and the original retail price of $40.00 | E8: Women | F8: Shorts | H8: 2 | I8: M | J8: NWT | K8: Free People | L8: Red | N8: FPCPRED1 | O8: Parent | P8: Size | Q8: Athletic | R8: Activewear | T8: 40 | U8: 30 | Y8: Not For Sale | AE8: https://images.urbndata.com/is/image/FreePeople/88138201_060_b/?$a15-pdp-detail-shot$&fit=constrain&fmt=webp&qlt=80&wid=1314
A9: FP009 | C9: NWT Free People Carpe Diem Short - Red - S | D9: NWT Free People Carpe Diem Short - Red The Carpe Diem shorts from FP Movement feature a relaxed, high-waisted fit designed for both performance and lounging. Crafted from durable, water-resistant fabric, these shorts include built-in briefs for added coverage and a comfortable stretch-knit waistband with a hidden interior pocket. Brand new with tags and the original retail price of $40.00 | E9: Women | F9: Shorts | H9: 1 | I9: S | J9: NWT | K9: Free People | L9: Red | N9: FPCPRED1 | O9: Child | Q9: Athletic | R9: Activewear | T9: 40 | U9: 30 | Y9: Not For Sale | AE9: https://images.urbndata.com/is/image/FreePeople/88138201_001_g/?$a15-pdp-detail-shot$&fit=constrain&fmt=webp&qlt=80&wid=1314
A10: FP010 | C10: NWT Free People Carpe Diem Short - White - S | D10: NWT Free People Carpe Diem Short - White - S The Carpe Diem shorts from FP Movement feature a relaxed, high-waisted fit designed for both performance and lounging. Crafted from durable, water-resistant fabric, these shorts include built-in briefs for added coverage and a comfortable stretch-knit waistband with a hidden interior pocket. Brand new with tags and the original retail price of $40.00 | E10: Women | F10: Shorts | H10: 1 | I10: S | J10: NWT | K10: Free People | L10: White | Q10: Athletic | R10: Activewear | T10: 40 | U10: 30 | Y10: Not For Sale | AE10: https://images.urbndata.com/is/image/FreePeople/88138201_010_d/?$a15-pdp-detail-shot$&fit=constrain&fmt=webp&qlt=80&wid=1314
A11: FP011 | C11: NWT Free People Carpe Diem Short - Yellow - M | D11: NWT Free People Carpe Diem Short - Yellow - M The Carpe Diem shorts from FP Movement feature a relaxed, high-waisted fit designed for both performance and lounging. Crafted from durable, water-resistant fabric, these shorts include built-in briefs for added coverage and a comfortable stretch-knit waistband with a hidden interior pocket. Brand new with tags and the original retail price of $40.00 | E11: Women | F11: Shorts | H11: 1 | I11: M | J11: NWT | K11: Free People | L11: Yellow | Q11: Athletic | R11: Activewear | T11: 40 | U11: 30 | Y11: Not For Sale | AE11: https://images.urbndata.com/is/image/FreePeople/88138201_072_d/?$a15-pdp-detail-shot$&fit=constrain&fmt=webp&qlt=80&wid=1314 | AF11: https://images.urbndata.com/is/image/FreePeople/88138201_072_f/?$a15-pdp-detail-shot$&fit=constrain&fmt=webp&qlt=80&wid=1314
A12: FP012 | C12: NWT Free People Power Play Cami - Bittersweet - XL | D12: NWT Free People Power Play Cami - Bittersweet - XL The Free People Power Play Cami features sheer lace shoulders and a delicate lace-trimmed neckline paired with a comfortable ribbed jersey bodice. This sleeveless top is crafted from midweight fabric, making it a versatile piece for layering or wearing on its own. Brand new with tags. Original retail price: $58. | E12: Women | F12: Tops | H12: 12 | I12: XL | J12: NWT | K12: Free People | L12: Brown | Q12: Lace | R12: Boudoir | S12: Bohemian | T12: 58 | U12: 35 | Y12: Not For Sale | AE12: https://images.urbndata.com/is/image/FreePeople/66211806_021_c/?$a15-pdp-detail-shot$&fit=constrain&fmt=webp&qlt=80&wid=1314
A13: FP013 | C13: NWT Free People Power Play Cami - Black - M | D13: NWT Free People Power Play Cami - Black - M The Free People Power Play Cami features sheer lace shoulders and a delicate lace-trimmed neckline paired with a comfortable ribbed jersey bodice. This sleeveless top is crafted from midweight fabric, making it a versatile piece for layering or wearing on its own. Brand new with tags. Original retail price: $58. | E13: Women | F13: Tops | H13: 5 | I13: M | J13: NWT | K13: Free People | L13: Black | Q13: Lace | R13: Boudoir | S13: Bohemian | T13: 58 | U13: 35 | Y13: Not For Sale | AE13: https://is4.revolveassets.com/images/p4/n/z/FREE-WS5364_V1.jpg
A14: FP014 | C14: NWT Free People Still Here Halter Cami - Black - M | D14: NWT Free People Still Here Halter Cami - Black - M Sweet, seamless fabrication defines this comfy halter cami from Intimately. This soft and stretchy top features a fitted, cropped silhouette with a classic halter neckline and thoughtful seam details. Perfect for layering or wearing on its own, it pairs effortlessly with your favorite denim for an easy, everyday look. Brand new with tags and the original retail price of $38.00 | E14: Women | F14: Tops | H14: 3 | I14: M | J14: NWT | K14: Free People | L14: Black | Q14: Casual | R14: Basics | T14: 38 | U14: 25 | Y14: Not For Sale | AE14: https://images.urbndata.com/is/image/FreePeople/96303847_001_oi/?$a15-pdp-detail-shot$&fit=constrain&qlt=80&wid=640
A15: FP015 | C15: NWT Free People Still Here Halter Cami - Dusted Blue - M | D15: NWT Free People Still Here Halter Cami - Dusted Blue - M Sweet, seamless fabrication defines this comfy halter cami from Intimately. Designed in a fitted, cropped silhouette, this top features soft, stretchy fabric, a flattering halter neckline, and seam details throughout. Pair with your favorite denim for easy, everyday outfitting. Brand new with tags Original retail price: $38 | E15: Women | F15: Tops | H15: 5 | I15: M | J15: NWT | K15: Free People | L15: Blue | Q15: Casual | R15: Basics | T15: 38 | U15: 25 | Y15: Not For Sale | AE15: https://encrypted-tbn1.gstatic.com/shopping?q=tbn:ANd9GcQs1WNwqrvYxZNAmz-lT8aTwA3MRsURkaL7zp2gJETtPxZJMAmI9SuZaP9ZHuQXH3SjBKDTBrQiA_IJUe5tkwWQDajABdQW
A16: FP016 | C16: NWT Free People Still Here Halter Cami - Red - XS | D16: NWT Free People Still Here Halter Cami - Red - XS Make everyday easy in this sleek halter cami designed with a soft, seamless fabrication. This comfy top features a slim-fitting, cropped silhouette with a plunging neckline and a bold open back for a spirit of femininity and creativity. Finished with fixed straps and seam detailing at the bust, it is the perfect lightweight piece to pair with your favorite denim. Brand new with tags Original retail price: $38 | E16: Women | F16: Tops | H16: 7 | I16: XS | J16: NWT | K16: Free People | L16: Red | Q16: Casual | R16: Basics | T16: 38 | U16: 25 | Y16: Not For Sale | AE16: https://media-photos.depop.com/b1/489150921/3719651887_fa165a7e3ffa420e8b7fc34b3b238e81/P0.jpg
A17: FP018 | C17: NWT Free People Still Here Halter Cami - White - S | D17: NWT Free People Still Here Halter Cami - White - S Sweet and seamless, this comfy halter cami from Intimately Free People is an essential base layer. It features a soft, stretchy fabrication in a fitted, cropped silhouette with a flattering plunge halter neckline and seam details throughout. Perfect for pairing with denim for an easy, effortless look. Brand new with tags and the original retail price of $38. | E17: Women | F17: Tops | H17: 5 | I17: S | J17: NWT | K17: Free People | L17: White | Q17: Casual | R17: Basics | T17: 38 | U17: 25 | Y17: Not For Sale | AE17: https://editorialist.com/thumbnails/600/2025/3/034/791/995/34791995~ivory_1741336167738_0.webp
A18: FP021 | C18: NWT Free People Sweet On You Bias Half Slip - Clean Ivory - XS | D18: NWT Free People Sweet On You Bias Half Slip - Clean Ivory - XS Forever femme, this delicate slip skirt features an all-over dotted jacquard pattern and bias-cut for a draped, flowy look. It is designed with a relaxed, high-rise silhouette and a maxi length that moves beautifully. Perfect for layering or wearing on its own, this versatile piece adds a romantic touch to any outfit. Brand new with tags. Original retail price $50.00. | E18: Women | F18: Skirts | H18: 4 | I18: XS | J18: NWT | K18: Free People | L18: White | Q18: Bohemian | R18: Festival | S18: Dainty | T18: 50 | U18: 30 | Y18: Not For Sale | AE18: https://images.urbndata.com/is/image/FreePeople/97448310_010_j/?$a15-pdp-detail-shot$&fit=constrain&fmt=webp&qlt=80&wid=1314
A19: FP022 | C19: NWT Free People Tank Only You - Black - XS | D19: NWT Free People Tank Only You - Black - XS So simple with sweet details, this classic tank is featured in a sheer ribbed cotton knit with ribbon-adorned lace trim. It features a form-fitting, full-length silhouette with a scoop neckline and lace straps with ribbon detailing. Crafted from a lightweight polyester and cotton blend, this semi-sheer top is perfect for layering or wearing on its own. Brand new with tags and the original retail price of $38.00. | E19: Women | F19: Tops | H19: 3 | I19: XS | J19: NWT | K19: Free People | L19: Black | Q19: Basics | R19: Ribbed | T19: 38 | U19: 25 | Y19: Not For Sale | AE19: https://content.backcountry.com/images/items/1200/FRP/FRPE0ZE/BLA.jpg
A20: FP023 | C20: NWT Free People Tank Only You - Heather Grey - M | D20: NWT Free People Tank Only You - Heather Grey - M So simple with sweet details, this classic form-fitting tank is featured in a semi-sheer ribbed cotton knit with lace straps and ribbon-adorned trim. Designed with a flattering scoop neckline and full length, it is the perfect base layer for any look. - 65% Polyester, 35% Cotton - 23.5 inch length - Machine wash coldBrand new with tags and the original retail price of $38.00 | E20: Women | F20: Tops | H20: 6 | I20: M | J20: NWT | K20: Free People | L20: Gray | Q20: Basics | R20: Ribbed | T20: 38 | U20: 25 | Y20: Not For Sale | AE20: https://sundiego.com/cdn/shop/files/unnamed_24c017c4-2f8d-4e34-beb6-416113a7e4a5.webp?v=1757048035
A21: UO002 | C21: Urban Outfitters Ashleigh Blue Halter Top - M | D21: Urban Outfitters Ashleigh Blue Halter Top A romantic and whimsical addition to your wardrobe, this fitted halter vest top features a plunging v-neckline and a chic split-front bodice. Crafted from a breathable linen blend in a solid light blue, it is designed with a seamed silhouette that hugs your curves. The open upper back and adjustable two-button halter closure offer a customizable fit, making it perfect for pairing with your favorite denim or flowing skirts for a festival-ready look. Brand new with tags $49.00 | E21: Women | F21: Tops | H21: 1 | I21: M | J21: NWT | K21: Urban Outfitters | L21: Blue | N21: UOTOP2 | O21: Parent | P21: Size | Q21: Y2K | R21: Casual | T21: 49 | U21: 30 | Y21: Not For Sale | AE21: https://di2ponv0v5otw.cloudfront.net/posts/2026/02/17/699480fcc4c837638fc16ed5/l_wp_699480fd14937706d8ff80b6.webp
A22: UO003 | C22: Urban Outfitters Ashleigh Blue Halter Top - S | D22: Urban Outfitters Ashleigh Blue Halter Top A romantic and whimsical addition to your wardrobe, this fitted halter vest top features a plunging v-neckline and a chic split-front bodice. Crafted from a breathable linen blend in a solid light blue, it is designed with a seamed silhouette that hugs your curves. The open upper back and adjustable two-button halter closure offer a customizable fit, making it perfect for pairing with your favorite denim or flowing skirts for a festival-ready look. Brand new with tags $49.00 | E22: Women | F22: Tops | H22: 1 | I22: S | J22: NWT | K22: Urban Outfitters | L22: Blue | N22: UOTOP2 | O22: Child | Q22: Y2K | R22: Casual | T22: 49 | U22: 30 | Y22: Not For Sale | AE22: https://di2ponv0v5otw.cloudfront.net/posts/2026/02/17/699480fcc4c837638fc16ed5/l_wp_699480fd14937706d8ff80b6.webp
A23: UO004 | C23: BDG Bradley Tiki Geo Top - L | D23: BDG Bradley Tiki Geo Top - L Channel effortless retro vibes with this BDG Bradley Tiki Geo Top. Featuring a bold geometric print inspired by vintage tiki aesthetics, this top offers a relaxed fit and a vibrant color palette perfect for sun-drenched days. The lightweight fabric and classic silhouette make it a versatile addition to your free-spirited wardrobe, whether paired with denim cutoffs or a flowing midi skirt. Brand new with tags Original retail price: $49.00 | E23: Women | F23: Dresses | H23: 1 | I23: L | J23: NWT | K23: BDG | L23: Brown | M23: White | Q23: Vacation | R23: Animal Print | S23: African | T23: 49 | U23: 30 | Y23: Not For Sale | AE23: https://images.urbndata.com/is/image/UrbanOutfitters/99180069_020_b5?$xlarge$&fit=constrain&qlt=80&wid=640
A24: UO006 | C24: Urban Outfitters Sleeveless Collared Top - Into the Gap (Light Blue) - M | D24: Urban Outfitters Sleeveless Collared Top - Into the Gap (Light Blue) - M Effortlessly cool and perfectly tailored, this sleeveless button-down top from Urban Outfitters is a versatile staple for your warm-weather wardrobe. Featuring a crisp collared neckline and a structured vest-inspired silhouette, it is crafted from a comfortable stretch-cotton blend in a chic light blue hue. Design details include a full button-front closure, princess seaming for a flattering slim fit, and a racerback design that adds a modern, athletic edge. Whether tucked into your favorite high-waisted denim or layered under a blazer, this top offers a sophisticated yet laid-back vibe for any occasion. Brand new with tags and the original retail price of $45. | E24: Women | F24: Tops | H24: 1 | I24: M | J24: NWT | K24: Urban Outfitters | L24: Blue | Q24: Y2K | R24: Collared | S24: Casual | T24: 40 | U24: 30 | Y24: Not For Sale | AE24: https://media-photos.depop.com/b1/52731319/3653232764_c30f6024e9c6472abd070638bbbeaa0d/P0.jpg
A25: UO007 | C25: Urban Outfitters Sleeveless Collared Top - Into the Gap (Light Blue) - S | D25: Urban Outfitters Sleeveless Collared Top - Into the Gap (Light Blue) - S Effortless and airy, this sleeveless collared top features a light blue wash that perfectly blends nostalgia with a modern silhouette. Designed with a structured collar and a relaxed, breezy fit, it is an ideal staple for layering or wearing on its own during sunny days. This versatile piece captures a creative spirit and individual style, making it a must-have addition to any boho-inspired wardrobe. Brand new with tags and the original retail price | E25: Women | F25: Tops | H25: 1 | I25: S | J25: NWT | K25: Urban Outfitters | L25: Blue | Q25: Y2K | R25: Collared | S25: Casual | T25: 40 | U25: 30 | Y25: Not For Sale | AE25: https://media-photos.depop.com/b1/52731319/3653232764_c30f6024e9c6472abd070638bbbeaa0d/P0.jpg
A26: UO008 | C26: Urban Outfitters Sleeveless Collared Top - Jet Black - M | D26: Urban Outfitters Sleeveless Collared Top - Jet Black - M Effortlessly chic and endlessly versatile, this sleeveless top from Urban Outfitters is a wardrobe essential. Crafted in a sleek jet black hue, it features a classic collared neckline and a streamlined silhouette that makes it perfect for layering or wearing solo. The soft, breathable fabric ensures all-day comfort, while the tailored fit adds a touch of sophistication to any ensemble. Pair it with your favorite high-waisted denim for a casual daytime look or tuck it into a midi skirt for an elevated evening outfit. Brand new with tags and the original retail price of $45.00 | E26: Women | F26: Tops | H26: 1 | I26: M | J26: NWT | K26: Urban Outfitters | L26: Black | Q26: Y2K | R26: Collared | S26: Casual | T26: 40 | U26: 30 | Y26: Not For Sale | AE26: https://encrypted-tbn0.gstatic.com/shopping?q=tbn:ANd9GcR2VXOLpmbqQv_XhQjofejfy53wOfDRHP39g-MMSM-Khz7e4hRW0wgckog2FhY5Z98yMK0nZ3eyCj0SIA4sA0Z5j3k-lkn5w3wzQjsOfzNg
A27: UO009 | C27: Urban Outfitters Sleeveless Collared Top - Jet Black - S | D27: Urban Outfitters Sleeveless Collared Top - Jet Black - S A versatile and stylish addition to your wardrobe, this sleeveless collared top is designed in a lightweight cotton-blend woven fabric for a trending vibe. It features a tailored slim fit with a button-down bodice and cutaway shoulders, making it perfect for layering or wearing solo. The classic collared neckline and regular length ensure a sophisticated look that transitions easily from casual outings to nights out. Brand new with tags and the original retail price $45 | E27: Women | F27: Tops | H27: 1 | I27: S | J27: NWT | K27: Urban Outfitters | L27: Black | Q27: Y2K | R27: Collared | S27: Casual | T27: 40 | U27: 30 | Y27: Not For Sale | AE27: https://encrypted-tbn0.gstatic.com/shopping?q=tbn:ANd9GcR2VXOLpmbqQv_XhQjofejfy53wOfDRHP39g-MMSM-Khz7e4hRW0wgckog2FhY5Z98yMK0nZ3eyCj0SIA4sA0Z5j3k-lkn5w3wzQjsOfzNg
A28: UO010 | C28: Urban Outfitters Sleeveless Collared Top - Party Girl Striped - M | D28: Urban Outfitters Sleeveless Collared Top - Party Girl Striped This breezy sleeveless top from Urban Outfitters features a classic collared neckline and a playful party girl striped pattern. Designed with a lightweight fabric and a relaxed fit, it is the perfect versatile piece for layering or wearing on its own during warm weather adventures. Brand new with tags and the original retail price | E28: Women | F28: Tops | H28: 1 | I28: M | J28: NWT | K28: Urban Outfitters | L28: Pink | M28: White | N28: UOTOP1 | O28: Parent | P28: Size | Q28: Y2K | R28: Collared | S28: Casual | T28: 40 | U28: 30 | Y28: Not For Sale | AE28: https://s7d2.scene7.com/is/image/nu/98947823_066_b?$pdp-regular$
A29: UO011 | C29: Urban Outfitters Sleeveless Collared Top - Party Girl Striped - XL | D29: Urban Outfitters Sleeveless Collared Top - Party Girl Striped This breezy sleeveless top from Urban Outfitters features a classic collared neckline and a playful party girl striped pattern. Designed with a lightweight fabric and a relaxed fit, it is the perfect versatile piece for layering or wearing on its own during warm weather adventures. Brand new with tags and the original retail price | E29: Women | F29: Tops | H29: 1 | I29: XL | J29: NWT | K29: Urban Outfitters | L29: Pink | M29: White | N29: UOTOP1 | O29: Child | Q29: Y2K | R29: Collared | S29: Casual | T29: 40 | U29: 30 | Y29: Not For Sale | AE29: https://s7d2.scene7.com/is/image/nu/98947823_066_b?$pdp-regular$

Sheet Color Mapping
A1: Red | B1: Color
A2: Pink | B2: Color
A3: Orange | B3: Color
A4: Yellow | B4: Color
A5: Green | B5: Color
A6: Blue | B6: Color
A7: Purple | B7: Color
A8: Gold | B8: Color
A9: Silver | B9: Color
A10: Black | B10: Color
A11: Gray | B11: Color
A12: White | B12: Color
... A15: Tan | B15: Color

Sheet Category
A1: =ARRAY_CONSTRAIN(ARRAYFORMULA(IFERROR(TRANSPOSE(_xlfn.UNIQUE(_xlfn._xlws.FILTER(Table_1[Category],Table_1[Department]='Listing Details'!E3))),"")), 1, 1) -> #ERROR!
A2: =ARRAY_CONSTRAIN(ARRAYFORMULA(IFERROR(TRANSPOSE(_xlfn.UNIQUE(_xlfn._xlws.FILTER(Table_1[Category],Table_1[Department]='Listing Details'!E4))),"")), 1, 1) -> #ERROR!
A3: =ARRAY_CONSTRAIN(ARRAYFORMULA(IFERROR(TRANSPOSE(_xlfn.UNIQUE(_xlfn._xlws.FILTER(Table_1[Category],Table_1[Department]='Listing Details'!E5))),"")), 1, 1) -> #ERROR!
A4: =ARRAY_CONSTRAIN(ARRAYFORMULA(IFERROR(TRANSPOSE(_xlfn.UNIQUE(_xlfn._xlws.FILTER(Table_1[Category],Table_1[Department]='Listing Details'!E6))),"")), 1, 1) -> #ERROR!
A5: =ARRAY_CONSTRAIN(ARRAYFORMULA(IFERROR(TRANSPOSE(_xlfn.UNIQUE(_xlfn._xlws.FILTER(Table_1[Category],Table_1[Department]='Listing Details'!E7))),"")), 1, 1) -> #ERROR!
A6: =ARRAY_CONSTRAIN(ARRAYFORMULA(IFERROR(TRANSPOSE(_xlfn.UNIQUE(_xlfn._xlws.FILTER(Table_1[Category],Table_1[Department]='Listing Details'!E8))),"")), 1, 1) -> #ERROR!
A7: =ARRAY_CONSTRAIN(ARRAYFORMULA(IFERROR(TRANSPOSE(_xlfn.UNIQUE(_xlfn._xlws.FILTER(Table_1[Category],Table_1[Department]='Listing Details'!E9))),"")), 1, 1) -> #ERROR!
A8: =ARRAY_CONSTRAIN(ARRAYFORMULA(IFERROR(TRANSPOSE(_xlfn.UNIQUE(_xlfn._xlws.FILTER(Table_1[Category],Table_1[Department]='Listing Details'!E10))),"")), 1, 1) -> #ERROR!
A9: =ARRAY_CONSTRAIN(ARRAYFORMULA(IFERROR(TRANSPOSE(_xlfn.UNIQUE(_xlfn._xlws.FILTER(Table_1[Category],Table_1[Department]='Listing Details'!E11))),"")), 1, 1) -> #ERROR!
A10: =ARRAY_CONSTRAIN(ARRAYFORMULA(IFERROR(TRANSPOSE(_xlfn.UNIQUE(_xlfn._xlws.FILTER(Table_1[Category],Table_1[Department]='Listing Details'!E12))),"")), 1, 1) -> #ERROR!
A11: =ARRAY_CONSTRAIN(ARRAYFORMULA(IFERROR(TRANSPOSE(_xlfn.UNIQUE(_xlfn._xlws.FILTER(Table_1[Category],Table_1[Department]='Listing Details'!E13))),"")), 1, 1) -> #ERROR!
A12: =ARRAY_CONSTRAIN(ARRAYFORMULA(IFERROR(TRANSPOSE(_xlfn.UNIQUE(_xlfn._xlws.FILTER(Table_1[Category],Table_1[Department]='Listing Details'!E14))),"")), 1, 1) -> #ERROR!
... A36: =ARRAY_CONSTRAIN(ARRAYFORMULA(IFERROR(TRANSPOSE(_xlfn.UNIQUE(_xlfn._xlws.FILTER(Table_1[Category],Table_1[Department]='Listing Details'!E38))),"")), 1, 1) -> #ERROR!
A37: =ARRAY_CONSTRAIN(ARRAYFORMULA(IFERROR(TRANSPOSE(_xlfn.UNIQUE(_xlfn._xlws.FILTER(Table_1[Category],Table_1[Department]='Listing Details'!E39))),"")), 1, 1) -> #ERROR! | F37: ='Listing Details'!F16 -> Tops
A38: =ARRAY_CONSTRAIN(ARRAYFORMULA(IFERROR(TRANSPOSE(_xlfn.UNIQUE(_xlfn._xlws.FILTER(Table_1[Category],Table_1[Department]='Listing Details'!E40))),"")), 1, 1) -> #ERROR!
A39: =ARRAY_CONSTRAIN(ARRAYFORMULA(IFERROR(TRANSPOSE(_xlfn.UNIQUE(_xlfn._xlws.FILTER(Table_1[Category],Table_1[Department]='Listing Details'!E41))),"")), 1, 1) -> #ERROR!
A40: =ARRAY_CONSTRAIN(ARRAYFORMULA(IFERROR(TRANSPOSE(_xlfn.UNIQUE(_xlfn._xlws.FILTER(Table_1[Category],Table_1[Department]='Listing Details'!E42))),"")), 1, 1) -> #ERROR!
A41: =ARRAY_CONSTRAIN(ARRAYFORMULA(IFERROR(TRANSPOSE(_xlfn.UNIQUE(_xlfn._xlws.FILTER(Table_1[Category],Table_1[Department]='Listing Details'!E43))),"")), 1, 1) -> #ERROR!
A42: =ARRAY_CONSTRAIN(ARRAYFORMULA(IFERROR(TRANSPOSE(_xlfn.UNIQUE(_xlfn._xlws.FILTER(Table_1[Category],Table_1[Department]='Listing Details'!E44))),"")), 1, 1) -> #ERROR!
A43: =ARRAY_CONSTRAIN(ARRAYFORMULA(IFERROR(TRANSPOSE(_xlfn.UNIQUE(_xlfn._xlws.FILTER(Table_1[Category],Table_1[Department]='Listing Details'!E45))),"")), 1, 1) -> #ERROR!
A44: =ARRAY_CONSTRAIN(ARRAYFORMULA(IFERROR(TRANSPOSE(_xlfn.UNIQUE(_xlfn._xlws.FILTER(Table_1[Category],Table_1[Department]='Listing Details'!E46))),"")), 1, 1) -> #ERROR!
A45: =ARRAY_CONSTRAIN(ARRAYFORMULA(IFERROR(TRANSPOSE(_xlfn.UNIQUE(_xlfn._xlws.FILTER(Table_1[Category],Table_1[Department]='Listing Details'!E47))),"")), 1, 1) -> #ERROR!
A46: =ARRAY_CONSTRAIN(ARRAYFORMULA(IFERROR(TRANSPOSE(_xlfn.UNIQUE(_xlfn._xlws.FILTER(Table_1[Category],Table_1[Department]='Listing Details'!E48))),"")), 1, 1) -> #ERROR!
A47: =ARRAY_CONSTRAIN(ARRAYFORMULA(IFERROR(TRANSPOSE(_xlfn.UNIQUE(_xlfn._xlws.FILTER(Table_1[Category],Table_1[Department]='Listing Details'!E49))),"")), 1, 1) -> #ERROR!
A48: =ARRAY_CONSTRAIN(ARRAYFORMULA(IFERROR(TRANSPOSE(_xlfn.UNIQUE(_xlfn._xlws.FILTER(Table_1[Category],Table_1[Department]='Listing Details'!E50))),"")), 1, 1) -> #ERROR!
A49: =ARRAY_CONSTRAIN(ARRAYFORMULA(IFERROR(TRANSPOSE(_xlfn.UNIQUE(_xlfn._xlws.FILTER(Table_1[Category],Table_1[Department]='Listing Details'!E51))),"")), 1, 1) -> #ERROR!
... A459: =ARRAY_CONSTRAIN(ARRAYFORMULA(IFERROR(TRANSPOSE(_xlfn.UNIQUE(_xlfn._xlws.FILTER(Table_1[Category],Table_1[Department]='Listing Details'!E461))),"")), 1, 1) -> #ERROR!

Sheet Subcat
A1: =ARRAY_CONSTRAIN(ARRAYFORMULA(IF(IFERROR(TRANSPOSE(_xlfn._xlws.FILTER(Table_1[[Subcategory ]],(Table_1[Department]='Listing Details'!E3)*(Table_1[Category]='Listing Details'!F3))),"")=0,"",IFERROR(TRANSPOSE(_xlfn._xlws.FILTER(Table_1[[Subcategory ]],(Table_1[Department]='Listing Details'!E3)*(Table_1[Category]='Listing Details'!F3))),""))), 1, 1) -> #ERROR!
A2: =ARRAY_CONSTRAIN(ARRAYFORMULA(IF(IFERROR(TRANSPOSE(_xlfn._xlws.FILTER(Table_1[[Subcategory ]],(Table_1[Department]='Listing Details'!E4)*(Table_1[Category]='Listing Details'!F4))),"")=0,"",IFERROR(TRANSPOSE(_xlfn._xlws.FILTER(Table_1[[Subcategory ]],(Table_1[Department]='Listing Details'!E4)*(Table_1[Category]='Listing Details'!F4))),""))), 1, 1) -> #ERROR!
A3: =ARRAY_CONSTRAIN(ARRAYFORMULA(IF(IFERROR(TRANSPOSE(_xlfn._xlws.FILTER(Table_1[[Subcategory ]],(Table_1[Department]='Listing Details'!E5)*(Table_1[Category]='Listing Details'!F5))),"")=0,"",IFERROR(TRANSPOSE(_xlfn._xlws.FILTER(Table_1[[Subcategory ]],(Table_1[Department]='Listing Details'!E5)*(Table_1[Category]='Listing Details'!F5))),""))), 1, 1) -> #ERROR!
A4: =ARRAY_CONSTRAIN(ARRAYFORMULA(IF(IFERROR(TRANSPOSE(_xlfn._xlws.FILTER(Table_1[[Subcategory ]],(Table_1[Department]='Listing Details'!E6)*(Table_1[Category]='Listing Details'!F6))),"")=0,"",IFERROR(TRANSPOSE(_xlfn._xlws.FILTER(Table_1[[Subcategory ]],(Table_1[Department]='Listing Details'!E6)*(Table_1[Category]='Listing Details'!F6))),""))), 1, 1) -> #ERROR!
A5: =ARRAY_CONSTRAIN(ARRAYFORMULA(IF(IFERROR(TRANSPOSE(_xlfn._xlws.FILTER(Table_1[[Subcategory ]],(Table_1[Department]='Listing Details'!E7)*(Table_1[Category]='Listing Details'!F7))),"")=0,"",IFERROR(TRANSPOSE(_xlfn._xlws.FILTER(Table_1[[Subcategory ]],(Table_1[Department]='Listing Details'!E7)*(Table_1[Category]='Listing Details'!F7))),""))), 1, 1) -> #ERROR!
A6: =ARRAY_CONSTRAIN(ARRAYFORMULA(IF(IFERROR(TRANSPOSE(_xlfn._xlws.FILTER(Table_1[[Subcategory ]],(Table_1[Department]='Listing Details'!E8)*(Table_1[Category]='Listing Details'!F8))),"")=0,"",IFERROR(TRANSPOSE(_xlfn._xlws.FILTER(Table_1[[Subcategory ]],(Table_1[Department]='Listing Details'!E8)*(Table_1[Category]='Listing Details'!F8))),""))), 1, 1) -> #ERROR!
A7: =ARRAY_CONSTRAIN(ARRAYFORMULA(IF(IFERROR(TRANSPOSE(_xlfn._xlws.FILTER(Table_1[[Subcategory ]],(Table_1[Department]='Listing Details'!E9)*(Table_1[Category]='Listing Details'!F9))),"")=0,"",IFERROR(TRANSPOSE(_xlfn._xlws.FILTER(Table_1[[Subcategory ]],(Table_1[Department]='Listing Details'!E9)*(Table_1[Category]='Listing Details'!F9))),""))), 1, 1) -> #ERROR!
A8: =ARRAY_CONSTRAIN(ARRAYFORMULA(IF(IFERROR(TRANSPOSE(_xlfn._xlws.FILTER(Table_1[[Subcategory ]],(Table_1[Department]='Listing Details'!E10)*(Table_1[Category]='Listing Details'!F10))),"")=0,"",IFERROR(TRANSPOSE(_xlfn._xlws.FILTER(Table_1[[Subcategory ]],(Table_1[Department]='Listing Details'!E10)*(Table_1[Category]='Listing Details'!F10))),""))), 1, 1) -> #ERROR!
A9: =ARRAY_CONSTRAIN(ARRAYFORMULA(IF(IFERROR(TRANSPOSE(_xlfn._xlws.FILTER(Table_1[[Subcategory ]],(Table_1[Department]='Listing Details'!E11)*(Table_1[Category]='Listing Details'!F11))),"")=0,"",IFERROR(TRANSPOSE(_xlfn._xlws.FILTER(Table_1[[Subcategory ]],(Table_1[Department]='Listing Details'!E11)*(Table_1[Category]='Listing Details'!F11))),""))), 1, 1) -> #ERROR!
A10: =ARRAY_CONSTRAIN(ARRAYFORMULA(IF(IFERROR(TRANSPOSE(_xlfn._xlws.FILTER(Table_1[[Subcategory ]],(Table_1[Department]='Listing Details'!E12)*(Table_1[Category]='Listing Details'!F12))),"")=0,"",IFERROR(TRANSPOSE(_xlfn._xlws.FILTER(Table_1[[Subcategory ]],(Table_1[Department]='Listing Details'!E12)*(Table_1[Category]='Listing Details'!F12))),""))), 1, 1) -> #ERROR!
A11: =ARRAY_CONSTRAIN(ARRAYFORMULA(IF(IFERROR(TRANSPOSE(_xlfn._xlws.FILTER(Table_1[[Subcategory ]],(Table_1[Department]='Listing Details'!E13)*(Table_1[Category]='Listing Details'!F13))),"")=0,"",IFERROR(TRANSPOSE(_xlfn._xlws.FILTER(Table_1[[Subcategory ]],(Table_1[Department]='Listing Details'!E13)*(Table_1[Category]='Listing Details'!F13))),""))), 1, 1) -> #ERROR!
A12: =ARRAY_CONSTRAIN(ARRAYFORMULA(IF(IFERROR(TRANSPOSE(_xlfn._xlws.FILTER(Table_1[[Subcategory ]],(Table_1[Department]='Listing Details'!E14)*(Table_1[Category]='Listing Details'!F14))),"")=0,"",IFERROR(TRANSPOSE(_xlfn._xlws.FILTER(Table_1[[Subcategory ]],(Table_1[Department]='Listing Details'!E14)*(Table_1[Category]='Listing Details'!F14))),""))), 1, 1) -> #ERROR!
... A194: =ARRAY_CONSTRAIN(ARRAYFORMULA(IF(IFERROR(TRANSPOSE(_xlfn._xlws.FILTER(Table_1[[Subcategory ]],(Table_1[Department]='Listing Details'!E196)*(Table_1[Category]='Listing Details'!F196))),"")=0,"",IFERROR(TRANSPOSE(_xlfn._xlws.FILTER(Table_1[[Subcategory ]],(Table_1[Department]='Listing Details'!E196)*(Table_1[Category]='Listing Details'!F196))),""))), 1, 1) -> #ERROR!

Sheet Size Lookup
A1: =ARRAY_CONSTRAIN(ARRAYFORMULA(IFERROR(TRANSPOSE(_xlfn.UNIQUE(_xlfn._xlws.FILTER(Table2[Size],Table2[Category]='Listing Details'!F3))),"")), 1, 1) -> #ERROR!
A2: =ARRAY_CONSTRAIN(ARRAYFORMULA(IFERROR(TRANSPOSE(_xlfn.UNIQUE(_xlfn._xlws.FILTER(Table2[Size],Table2[Category]='Listing Details'!F4))),"")), 1, 1) -> #ERROR!
A3: =ARRAY_CONSTRAIN(ARRAYFORMULA(IFERROR(TRANSPOSE(_xlfn.UNIQUE(_xlfn._xlws.FILTER(Table2[Size],Table2[Category]='Listing Details'!F5))),"")), 1, 1) -> #ERROR!
A4: =ARRAY_CONSTRAIN(ARRAYFORMULA(IFERROR(TRANSPOSE(_xlfn.UNIQUE(_xlfn._xlws.FILTER(Table2[Size],Table2[Category]='Listing Details'!F6))),"")), 1, 1) -> #ERROR!
A5: =ARRAY_CONSTRAIN(ARRAYFORMULA(IFERROR(TRANSPOSE(_xlfn.UNIQUE(_xlfn._xlws.FILTER(Table2[Size],Table2[Category]='Listing Details'!F7))),"")), 1, 1) -> #ERROR!
A6: =ARRAY_CONSTRAIN(ARRAYFORMULA(IFERROR(TRANSPOSE(_xlfn.UNIQUE(_xlfn._xlws.FILTER(Table2[Size],Table2[Category]='Listing Details'!F8))),"")), 1, 1) -> #ERROR!
A7: =ARRAY_CONSTRAIN(ARRAYFORMULA(IFERROR(TRANSPOSE(_xlfn.UNIQUE(_xlfn._xlws.FILTER(Table2[Size],Table2[Category]='Listing Details'!F9))),"")), 1, 1) -> #ERROR!
A8: =ARRAY_CONSTRAIN(ARRAYFORMULA(IFERROR(TRANSPOSE(_xlfn.UNIQUE(_xlfn._xlws.FILTER(Table2[Size],Table2[Category]='Listing Details'!F10))),"")), 1, 1) -> #ERROR!
A9: =ARRAY_CONSTRAIN(ARRAYFORMULA(IFERROR(TRANSPOSE(_xlfn.UNIQUE(_xlfn._xlws.FILTER(Table2[Size],Table2[Category]='Listing Details'!F11))),"")), 1, 1) -> #ERROR!
A10: =ARRAY_CONSTRAIN(ARRAYFORMULA(IFERROR(TRANSPOSE(_xlfn.UNIQUE(_xlfn._xlws.FILTER(Table2[Size],Table2[Category]='Listing Details'!F12))),"")), 1, 1) -> #ERROR!
A11: =ARRAY_CONSTRAIN(ARRAYFORMULA(IFERROR(TRANSPOSE(_xlfn.UNIQUE(_xlfn._xlws.FILTER(Table2[Size],Table2[Category]='Listing Details'!F13))),"")), 1, 1) -> #ERROR!
A12: =ARRAY_CONSTRAIN(ARRAYFORMULA(IFERROR(TRANSPOSE(_xlfn.UNIQUE(_xlfn._xlws.FILTER(Table2[Size],Table2[Category]='Listing Details'!F14))),"")), 1, 1) -> #ERROR!
... A45: =ARRAY_CONSTRAIN(ARRAYFORMULA(IFERROR(TRANSPOSE(_xlfn.UNIQUE(_xlfn._xlws.FILTER(Table2[Size],Table2[Category]='Listing Details'!F47))),"")), 1, 1) -> #ERROR!

Sheet Sheet2
A1: {=IFERROR(TRANSPOSE(_xlws.FILTER(Options!$C$2:$C$701,(Options!$A$2:$A$701=#REF!)*(Options!$B$2:$B$701=#REF!))),"")}
A2: #NAME?
A3: #NAME?
A4: #NAME?
A5: #NAME?
A6: #NAME?
A7: #NAME?
A8: {=IFERROR(TRANSPOSE(_xlws.FILTER(Options!$C$2:$C$701,(Options!$A$2:$A$701=#REF!)*(Options!$B$2:$B$701=#REF!))),"")}
A9: {=IFERROR(TRANSPOSE(_xlws.FILTER(Options!$C$2:$C$701,(Options!$A$2:$A$701=#REF!)*(Options!$B$2:$B$701=#REF!))),"")}
A10: {=IFERROR(TRANSPOSE(_xlws.FILTER(Options!$C$2:$C$701,(Options!$A$2:$A$701=#REF!)*(Options!$B$2:$B$701=#REF!))),"")}
A11: {=IFERROR(TRANSPOSE(_xlws.FILTER(Options!$C$2:$C$701,(Options!$A$2:$A$701=#REF!)*(Options!$B$2:$B$701=#REF!))),"")}
A12: {=IFERROR(TRANSPOSE(_xlws.FILTER(Options!$C$2:$C$701,(Options!$A$2:$A$701=#REF!)*(Options!$B$2:$B$701=#REF!))),"")}
A13: {=IFERROR(TRANSPOSE(_xlws.FILTER(Options!$C$2:$C$701,(Options!$A$2:$A$701=#REF!)*(Options!$B$2:$B$701=#REF!))),"")}
A14: {=IFERROR(TRANSPOSE(_xlws.FILTER(Options!$C$2:$C$701,(Options!$A$2:$A$701=#REF!)*(Options!$B$2:$B$701=#REF!))),"")}
A15: {=IFERROR(TRANSPOSE(_xlws.FILTER(Options!$C$2:$C$701,(Options!$A$2:$A$701=#REF!)*(Options!$B$2:$B$701=#REF!))),"")}
A16: {=IFERROR(TRANSPOSE(_xlws.FILTER(Options!$C$2:$C$701,(Options!$A$2:$A$701=#REF!)*(Options!$B$2:$B$701=#REF!))),"")}
A17: {=IFERROR(TRANSPOSE(_xlws.FILTER(Options!$C$2:$C$701,(Options!$A$2:$A$701=#REF!)*(Options!$B$2:$B$701=#REF!))),"")}
A18: #NAME?
A19: #NAME?
A20: #NAME?
A21: #NAME?
A22: {=IFERROR(TRANSPOSE(_xlws.FILTER(Options!$C$2:$C$701,(Options!$A$2:$A$701=#REF!)*(Options!$B$2:$B$701=#REF!))),"")}
A23: {=IFERROR(TRANSPOSE(_xlws.FILTER(Options!$C$2:$C$701,(Options!$A$2:$A$701=#REF!)*(Options!$B$2:$B$701=#REF!))),"")}
A24: #NAME?
A25: #NAME?
A26: #NAME?
A27: #NAME?
A28: #NAME?
A29: #NAME?
A30: #NAME?
A31: #NAME?
A32: #NAME?
A33: #NAME?
A34: #NAME?
A35: #NAME?
... A38: #NAME?
A39: {=IFERROR(TRANSPOSE(_xlws.FILTER(Options!$C$2:$C$701,(Options!$A$2:$A$701=#REF!)*(Options!$B$2:$B$701=#REF!))),"")}
A40: {=IFERROR(TRANSPOSE(_xlws.FILTER(Options!$C$2:$C$701,(Options!$A$2:$A$701='Listing Details'!E3)*(Options!$B$2:$B$701='Listing Details'!F3))),"")}
A41: {=IFERROR(TRANSPOSE(_xlws.FILTER(Options!$C$2:$C$701,(Options!$A$2:$A$701=#REF!)*(Options!$B$2:$B$701=#REF!))),"")}
A42: {=IFERROR(TRANSPOSE(_xlws.FILTER(Options!$C$2:$C$701,(Options!$A$2:$A$701='Listing Details'!E4)*(Options!$B$2:$B$701='Listing Details'!F4))),"")}
...

Sheet Options
A1: Department | B1: Category | C1: Subcategory | D1: Color1/Color2 | E1: =IFERROR(DUMMYFUNCTION("ARRAY_CONSTRAIN(ARRAYFORMULA(UNIQUE(Options!$A$2:$A$516)), 5, 1)"),"Women") -> Women
A2: Women | B2: Accessories | C2: Belts | E2: Men
A3: Women | B3: Accessories | C3: Face Masks | E3: Kids
A4: Women | B4: Accessories | C4: Glasses | E4: Home
A5: Women | B5: Accessories | C5: Gloves & Mittens | E5: Pets
A6: Women | B6: Accessories | C6: Hair Accessories | E6: Electronics
A7: Women | B7: Accessories | C7: Hats
A8: Women | B8: Accessories | C8: Hosiery & Socks
A9: Women | B9: Accessories | C9: Key & Card Holders
A10: Women | B10: Accessories | C10: Laptop Cases
A11: Women | B11: Accessories | C11: Phone Cases
A12: Women | B12: Accessories | C12: Scarves & Wraps
A13: Women | B13: Accessories | C13: Sunglasses
A14: Women | B14: Accessories | C14: Tablet Cases
A15: Women | B15: Accessories | C15: Umbrellas
A16: Women | B16: Accessories | C16: Watches
A17: Women | B17: Ao Dais
A18: Women | B18: Bags | C18: Baby Bags
A19: Women | B19: Bags | C19: Backpacks
A20: Women | B20: Bags | C20: Clutches & Wristlets
A21: Women | B21: Bags | C21: Cosmetic Bags & Cases
A22: Women | B22: Bags | C22: Crossbody Bags
A23: Women | B23: Bags | C23: Hobos
A24: Women | B24: Bags | C24: Laptop Bags
A25: Women | B25: Bags | C25: Mini Bags
A26: Women | B26: Bags | C26: Satchels
A27: Women | B27: Bags | C27: Shoulder Bags
A28: Women | B28: Bags | C28: Totes
A29: Women | B29: Bags | C29: Travel Bags
... A39: Women | B39: Bath & Body | C39: Tools
A40: Women | B40: Cheongsams & Qipaos
A41: Women | B41: Dirndls
A42: Women | B42: Dresses | C42: Asymmetrical | D42: Pink
A43: Women | B43: Dresses | C43: Backless | D43: Orange
A44: Women | B44: Dresses | C44: High Low | D44: Yellow
A45: Women | B45: Dresses | C45: Long Sleeve | D45: Green
A46: Women | B46: Dresses | C46: Maxi | D46: Blue
A47: Women | B47: Dresses | C47: Midi | D47: Purple
A48: Women | B48: Dresses | C48: Mini | D48: Gold
A49: Women | B49: Dresses | C49: One Shoulder | D49: Silver
...

Sheet Size Options
A1: Category | B1: Size
A2: Accessories | B2: OS
A3: Bags | B3: OS
